In Rust, error handling is done without exceptions, which are common in many other programming languages. Instead, Rust encourages the use of the `Result` type for recoverable errors and the `panic!` macro for unrecoverable errors. This approach is more explicit and involves pattern matching to handle various outcomes of a function that may fail.

### Using the `Result` Type:

The `Result` type is an enum with the variants `Ok` and `Err`. Functions that can fail will return a `Result`, where an `Ok` value represents success and contains the successful value, and an `Err` value represents failure and contains an error value explaining what went wrong.

Here's a simple example of how you might use the `Result` type in a function that reads text from a file:

```rust
use std::fs::File;
use std::io::{self, Read};

// This function returns a `Result` type with a `String` in the `Ok` variant
// and an `io::Error` in the `Err` variant.
fn read_text_from_file(path: &str) -> Result<String, io::Error> {
    // Try to open the file.
    let mut file = match File::open(path) {
        // If the file opens successfully, the `Ok` value is returned.
        Ok(file) => file,
        // If there's an error, it's returned immediately to the calling function.
        Err(e) => return Err(e),
    };

    let mut text = String::new();
    // Try to read the text from the file.
    match file.read_to_string(&mut text) {
        // If the reading is successful, the text is returned within an `Ok`.
        Ok(_) => Ok(text),
        // If there's an error, it's returned immediately to the calling function.
        Err(e) => Err(e),
    }
}

fn main() {
    match read_text_from_file("filename.txt") {
        Ok(text) => {
            // If the function succeeds, you'll have the text here.
            println!("File content: {}", text);
        }
        Err(e) => {
            // If the function fails, you'll handle the error here.
            println!("Failed to read the file: {}", e);
        }
    }
}
```

In this example, the `read_text_from_file` function is designed to propagate errors to the calling code where they can be handled appropriately. This is a common pattern in Rust, avoiding the need for exceptions and ensuring that errors are handled explicitly.

### The `?` Operator:

Rust provides a `?` operator to make working with the `Result` type easier. This operator unwraps a successful result (an `Ok` value) and immediately returns from the function for an error result (an `Err` value), propagating the error to the caller. Here's how you can use it:

```rust
fn read_text_from_file(path: &str) -> Result<String, io::Error> {
    let mut file = File::open(path)?;
    let mut text = String::new();
    file.read_to_string(&mut text)?;
    Ok(text)
}
```

In this version of the function, if `File::open` or `read_to_string` encounters an error, the `?` operator will immediately return the error (`Err` variant) to the caller of `read_text_from_file`.

### Unrecoverable Errors with `panic!`:

When an error occurs that is unrecoverable, such as an essential invariant violation, Rust has the `panic!` macro. When this is invoked, the program will print a failure message, unwind and clean up the stack, and then quit. This is less graceful than handling errors with `Result`, but it's appropriate for non-recoverable errors.

```rust
fn main() {
    let result = panic::catch_unwind(|| {
        println!("This will be executed.");
        panic!("Unrecoverable error occurred!"); // This causes a panic.
    });

    if result.is_err() {
        println!("Caught the panic.");
    }
}
```

In this example, `panic!` is used to demonstrate an unrecoverable error. The program will stop executing further normal operations, start unwinding, and display a panic message.

By handling errors explicitly using `Result` and `panic!`, Rust programs make it clear when errors are expected and recoverable and when they're not. This explicitness also increases the reliability of Rust code, making it easier to reason about error cases and prevent unexpected crashes.